Workbook

Sheet PARTICIPANTES
A1: ID. Model | B1: Participante | C1: E-mail | D1: Origem | E1: Grafo | F1: Entregue | G1: Avaliação | H1: NF | K1: Resultados
A2: 1 | B2: aaaaaa | C2: aaaaaa | D2: Pós-graduação | E2: Não | F2: Sim | G2: 8 | H2: =MODELAGEM_1!X$7 -> 0.34941447 | K2: Grafo | L2: Sim | M2: =COUNTIF($E$2:$E$58,"=Sim") -> 19 | N2: Entregue | O2: Sim | P2: =COUNTIF($E$2:$E$58,"=Sim") -> 19
A3: 2 | B3: bbbbbb | C3: bbbbbb | D3: Pós-graduação | E3: Não | F3: Sim | G3: 8 | H3: =MODELAGEM_2!X$7 -> 0.12621495 | L3: Não | M3: =COUNTIF($E$2:$E$58,"=Não") -> 14 | O3: Não | P3: =COUNTIF($E$2:$E$58,"=Não") -> 14
A4: 3 | B4: ccccccc | C4: ccccccc | D4: Pós-graduação | E4: Não | F4: Sim | G4: 4 | H4: =MODELAGEM_3!X$7 -> 0.29203146
A5: 4 | B5: dddddd | C5: dddddd | D5: Pós-graduação | E5: Sim | F5: Sim | G5: 8 | H5: =MODELAGEM_4!X$7 -> 0.23424516
A6: 5 | B6: eeeeee | C6: eeeeee | D6: Graduação | E6: Não | F6: Sim | G6: 8 | H6: =MODELAGEM_5!X$7 -> 0.38358843
A7: 6 | B7: fffffffff | C7: fffffffff | D7: Graduação | E7: Não | F7: Sim | G7: 8.5 | H7: =MODELAGEM_6!X$7 -> 0.37797161
A8: 7 | B8: gggggg | C8: gggggg | D8: Graduação | E8: Sim | F8: Sim | G8: 8.5 | H8: =MODELAGEM_7!X$7 -> 0.30397496 | J8: Grafo
A9: 8 | B9: hhhhhh | C9: hhhhhh | D9: Graduação | E9: Sim | F9: Sim | G9: 8 | H9: =MODELAGEM_8!X$7 -> 0.21477206 | J9: Grafo
A10: 9 | B10: iiiiiiiiii | C10: iiiiiiiiii | D10: Graduação | E10: Não | F10: Sim | G10: 6 | H10: =MODELAGEM_9!X$7 -> 0.31511939
A11: 11 | B11: jjjjjjjjjjj | C11: jjjjjjjjjjj | D11: Graduação | E11: Sim | F11: Sim | G11: 8 | H11: =MODELAGEM_11!X$7 -> 0.28676228 | J11: Grafo
A12: 12 | B12: kkkkkk | C12: kkkkkk | D12: Graduação | E12: Não | F12: Sim | G12: 7 | H12: =MODELAGEM_12!X$7 -> 0.19258603
A13: 13 | B13: lllllllllll | C13: lllllllllll | D13: Graduação | E13: Sim | F13: Sim | G13: 8 | H13: =MODELAGEM_13!X$7 -> 0.34096503 | J13: Grafo
A14: 15 | B14: mmm | C14: mmm | D14: Graduação | E14: Não | F14: Sim | G14: 7 | H14: =MODELAGEM_15!X$7 -> 0.37417154
A15: 16 | B15: nnnnnnnn | C15: nnnnnnnn | D15: Graduação | E15: Não | F15: Sim | G15: 8 | H15: =MODELAGEM_16!X$7 -> 0.26397449
A16: 17 | B16: ooooooo | C16: ooooooo | D16: Graduação | E16: Sim | F16: Sim | G16: 7 | H16: =MODELAGEM_17!X$7 -> 0.41920927 | J16: Grafo
A17: 18 | B17: ppppppp | C17: ppppppp | D17: Graduação | E17: Sim | F17: Sim | G17: 8 | H17: =MODELAGEM_18!X$7 -> 0.39810584 | J17: Grafo
A18: 19 | B18: qqqqqq | C18: qqqqqq | D18: Graduação | E18: Não | F18: Sim | G18: 9 | H18: =MODELAGEM_19!X$7 -> 0.34367153
A19: 20 | B19: rrrrrrrr | C19: rrrrrrrr | D19: Graduação | E19: Não | F19: Sim | G19: 4 | H19: =MODELAGEM_20!X$7 -> 0.34909874
A20: 21 | B20: ssssssss | C20: ssssssss | D20: Graduação | E20: Não | F20: Sim | G20: 6 | H20: =MODELAGEM_21!X$7 -> 0.2061004
A21: 22 | B21: ttttttttt | C21: ttttttttt | D21: Graduação | E21: Sim | F21: Sim | G21: 6 | H21: =MODELAGEM_22!X$7 -> 0.23153956 | J21: Grafo
A22: 23 | B22: uuuuuu | C22: uuuuuu | D22: Externo | E22: Sim | F22: Sim | G22: 4 | H22: =MODELAGEM_23!X$7 -> 0.11482052
A23: 24 | B23: vvvvvvv | C23: vvvvvvv | D23: Externo | E23: Sim | F23: Sim | G23: 9 | H23: =MODELAGEM_24!X$7 -> 0.41178872
A24: 25 | B24: xxxxxxx | C24: xxxxxxx | D24: Externo | E24: Não | F24: Não | G24: 6 | H24: =MODELAGEM_25!X$7 -> 0.22578825
A25: 26 | B25: zzzzzzzz | C25: zzzzzzzz | D25: Externo | E25: Sim | F25: Sim | G25: 8 | H25: =MODELAGEM_26!X$7 -> 0.37660796
A26: 27 | B26: ababababababa | C26: ababababababa | D26: Externo | E26: Sim | F26: Sim | G26: 8 | H26: =MODELAGEM_27!X$7 -> 0.31819086
A27: 28 | B27: acacacacacacaca | C27: acacacacacacaca | D27: Externo | E27: Não | F27: Não | G27: 6 | H27: =MODELAGEM_28!X$7 -> 0.19622948
A28: 29 | B28: babababababa | C28: babababababa | D28: Graduação | E28: Sim | F28: Sim | G28: 7 | H28: =MODELAGEM_29!X$7 -> 0.34858001
A29: 30 | B29: kaklsolalaolsoal | C29: kaklsolalaolsoal | D29: Graduação | E29: Sim | F29: Sim | G29: 7 | H29: =MODELAGEM_30!X$7 -> 0.37324085
A30: 31 | B30: allkskskakakl | C30: allkskskakakl | D30: Graduação | E30: Sim | F30: Não | G30: 6 | H30: =MODELAGEM_31!X$7 -> 0.22745187
A31: 32 | B31: allalslakska | C31: allalslakska | D31: Externo | E31: Sim | F31: Não
A32: 33 | B32: kallslskakka | C32: kallslskakka | D32: Externo | E32: Sim | F32: Sim
A33: 34 | B33: alakksjksijjka | C33: alakksjksijjka | D33: Externo | E33: Sim | F33: Não
A34: 35 | B34: akklskskkajjkakl | C34: akklskskkajjkakl | D34: Externo | E34: Sim | F34: Não

Sheet CONSOLIDADO
B2: N. ELEM {KG} | C2: N. ELEM {MC} | D2: TP | E2: TN | F2: FN | G2: FP | H2: COMPATÍVEIS | I2: INCOMPATÍVEIS | J2: PRECISÃO | K2: COBERTURA | L2: ACURÁCIA
A3: ENTIDADES | B3: =GRAFO!J2 -> 29 | C3: =AVERAGE(MODELAGEM_1!N4,MODELAGEM_2!N4,MODELAGEM_3!N4,MODELAGEM_4!N4,MODELAGEM_5!N4,MODELAGEM_6!N4,MODELAGEM_7!N4,MODELAGEM_8!N4,MODELAGEM_9!N4,MODELAGEM_11!N4,MODELAGEM_12!N4,MODELAGEM_13!N4,MODELAGEM_15!N4,MODELAGEM_16!N4,MODELAGEM_17!N4,MODELAGEM_18!N4,MODELAGEM_19!N4,MODELAGEM_20!N4,MODELAGEM_21!N4,MODELAGEM_22!N4,MODELAGEM_23!N4,MODELAGEM_24!N4,MODELAGEM_25!N4,MODELAGEM_26!N4,MODELAGEM_27!N4) -> 24.36 | D3: =AVERAGE(MODELAGEM_1!O4,MODELAGEM_2!O4,MODELAGEM_3!O4,MODELAGEM_4!O4,MODELAGEM_5!O4,MODELAGEM_6!O4,MODELAGEM_7!O4,MODELAGEM_8!O4,MODELAGEM_9!O4,MODELAGEM_11!O4,MODELAGEM_12!O4,MODELAGEM_13!O4,MODELAGEM_15!O4,MODELAGEM_16!O4,MODELAGEM_17!O4,MODELAGEM_18!O4,MODELAGEM_19!O4,MODELAGEM_20!O4,MODELAGEM_21!O4,MODELAGEM_22!O4,MODELAGEM_23!O4,MODELAGEM_24!O4,MODELAGEM_25!O4,MODELAGEM_26!O4,MODELAGEM_27!O4) -> 12.88 | E3: =C3-G3 -> 12.88 | F3: =B3-D3 -> 16.12 | G3: =C3-D3 -> 11.48 | H3: =D3+E3 -> 25.76 | I3: =F3+G3 -> 27.6 | J3: =D3/(D3+G3) -> 0.52873563 | K3: =D3/(D3+F3) -> 0.44413793 | L3: =(D3+E3)/(D3+E3+F3+G3) -> 0.48275862
A4: RELAÇÕES (SR) | B4: =GRAFO!J3 -> 41 | C4: =AVERAGE(MODELAGEM_1!N5,MODELAGEM_2!N5,MODELAGEM_3!N5,MODELAGEM_4!N5,MODELAGEM_5!N5,MODELAGEM_6!N5,MODELAGEM_7!N5,MODELAGEM_8!N5,MODELAGEM_9!N5,MODELAGEM_11!N5,MODELAGEM_12!N5,MODELAGEM_13!N5,MODELAGEM_15!N5,MODELAGEM_16!N5,MODELAGEM_17!N5,MODELAGEM_18!N5,MODELAGEM_19!N5,MODELAGEM_20!N5,MODELAGEM_21!N5,MODELAGEM_22!N5,MODELAGEM_23!N5,MODELAGEM_24!N5,MODELAGEM_25!N5,MODELAGEM_26!N5,MODELAGEM_27!N5) -> 25.36 | D4: =AVERAGE(MODELAGEM_1!O5,MODELAGEM_2!O5,MODELAGEM_3!O5,MODELAGEM_4!O5,MODELAGEM_5!O5,MODELAGEM_6!O5,MODELAGEM_7!O5,MODELAGEM_8!O5,MODELAGEM_9!O5,MODELAGEM_11!O5,MODELAGEM_12!O5,MODELAGEM_13!O5,MODELAGEM_15!O5,MODELAGEM_16!O5,MODELAGEM_17!O5,MODELAGEM_18!O5,MODELAGEM_19!O5,MODELAGEM_20!O5,MODELAGEM_21!O5,MODELAGEM_22!O5,MODELAGEM_23!O5,MODELAGEM_24!O5,MODELAGEM_25!O5,MODELAGEM_26!O5,MODELAGEM_27!O5) -> 6.76 | E4: =C4-G4 -> 6.76 | F4: =B4-D4 -> 34.24 | G4: =C4-D4 -> 18.6 | H4: =D4+E4 -> 13.52 | I4: =F4+G4 -> 52.84 | J4: =D4/(D4+G4) -> 0.26656151 | K4: =D4/(D4+F4) -> 0.16487805 | L4: =(D4+E4)/(D4+E4+F4+G4) -> 0.20373719
A5: RELAÇÕES (CR) | B5: =GRAFO!J3 -> 41 | C5: =AVERAGE(MODELAGEM_1!N6,MODELAGEM_2!N6,MODELAGEM_3!N6,MODELAGEM_4!N6,MODELAGEM_5!N6,MODELAGEM_6!N6,MODELAGEM_7!N6,MODELAGEM_8!N6,MODELAGEM_9!N6,MODELAGEM_11!N6,MODELAGEM_12!N6,MODELAGEM_13!N6,MODELAGEM_15!N6,MODELAGEM_16!N6,MODELAGEM_17!N6,MODELAGEM_18!N6,MODELAGEM_19!N6,MODELAGEM_20!N6,MODELAGEM_21!N6,MODELAGEM_22!N6,MODELAGEM_23!N6,MODELAGEM_24!N6,MODELAGEM_25!N6,MODELAGEM_26!N6,MODELAGEM_27!N6) -> 25.36 | D5: =AVERAGE(MODELAGEM_1!O6,MODELAGEM_2!O6,MODELAGEM_3!O6,MODELAGEM_4!O6,MODELAGEM_5!O6,MODELAGEM_6!O6,MODELAGEM_7!O6,MODELAGEM_8!O6,MODELAGEM_9!O6,MODELAGEM_11!O6,MODELAGEM_12!O6,MODELAGEM_13!O6,MODELAGEM_15!O6,MODELAGEM_16!O6,MODELAGEM_17!O6,MODELAGEM_18!O6,MODELAGEM_19!O6,MODELAGEM_20!O6,MODELAGEM_21!O6,MODELAGEM_22!O6,MODELAGEM_23!O6,MODELAGEM_24!O6,MODELAGEM_25!O6,MODELAGEM_26!O6,MODELAGEM_27!O6) -> 6.24 | E5: =C5-G5 -> 6.24 | F5: =B5-D5 -> 34.76 | G5: =C5-D5 -> 19.12 | H5: =D5+E5 -> 12.48 | I5: =F5+G5 -> 53.88 | J5: =D5/(D5+G5) -> 0.24605678 | K5: =D5/(D5+F5) -> 0.15219512 | L5: =(D5+E5)/(D5+E5+F5+G5) -> 0.1880651

Sheet GRAFO
A1: ENTIDADES IDENTIFICADAS NO GRAFO (ETAPA 1) | C1: TRIPLAS | G1: RELAÇÕES | I1: RESULTADOS | L1: entity+entity | M1: entity+relation+entity
A2: aeronautica | C2: nivel | D2: rdf:type | E2: entity | G2: rdf:type | I2: N. ENTIDADES: | J2: =COUNTA(A2:A30) -> 29 | L2: =C2 & "-" & E2 -> nivel-entity | M2: =C2 & "-" & D2 & "-" & E2 -> nivel-rdf:type-entity
A3: comandante_supremo | C3: politico | D3: rdfs:subClassOf | E3: nivel | G3: rdfs:Class | I3: N. RELAÇÕES: | J3: =COUNTA(C2:C42) -> 41 | L3: =C3 & "-" & E3 -> politico-nivel | M3: =C3 & "-" & D3 & "-" & E3 -> politico-rdfs:subClassOf-nivel
A4: comando_e_controle | C4: estrategico | D4: rdfs:subClassOf | E4: nivel | G4: rdfs:subClassOf | L4: =C4 & "-" & E4 -> estrategico-nivel | M4: =C4 & "-" & D4 & "-" & E4 -> estrategico-rdfs:subClassOf-nivel
A5: comando_supremo | C5: tatico | D5: rdfs:subClassOf | E5: nivel | G5: rdfs:seeAlso | L5: =C5 & "-" & E5 -> tatico-nivel | M5: =C5 & "-" & D5 & "-" & E5 -> tatico-rdfs:subClassOf-nivel
A6: comandos_operacionais | C6: operacional | D6: rdfs:subClassOf | E6: nivel | G6: rdfs:comment | L6: =C6 & "-" & E6 -> operacional-nivel | M6: =C6 & "-" & D6 & "-" & E6 -> operacional-rdfs:subClassOf-nivel
A7: defesa_da_patria | C7: comandos_operacionais | D7: c2rm:responsible_for | E7: operacional | G7: owl:equivalentClass | L7: =C7 & "-" & E7 -> comandos_operacionais-operacional | M7: =C7 & "-" & D7 & "-" & E7 -> comandos_operacionais-c2rm:responsible_for-operacional
A8: emprego | C8: logistica | D8: rdfs:subClassOf | E8: estruturas | G8: c2rm:applied_to | L8: =C8 & "-" & E8 -> logistica-estruturas | M8: =C8 & "-" & D8 & "-" & E8 -> logistica-rdfs:subClassOf-estruturas
A9: entity | C9: inteligencia | D9: rdfs:subClassOf | E9: estruturas | G9: c2rm:responsible_for | L9: =C9 & "-" & E9 -> inteligencia-estruturas | M9: =C9 & "-" & D9 & "-" & E9 -> inteligencia-rdfs:subClassOf-estruturas
A10: estrategico | C10: comando_e_controle | D10: rdfs:subClassOf | E10: estruturas | L10: =C10 & "-" & E10 -> comando_e_controle-estruturas | M10: =C10 & "-" & D10 & "-" & E10 -> comando_e_controle-rdfs:subClassOf-estruturas
A11: estruturas | C11: operacional | D11: rdfs:seeAlso | E11: inteligencia | L11: =C11 & "-" & E11 -> operacional-inteligencia | M11: =C11 & "-" & D11 & "-" & E11 -> operacional-rdfs:seeAlso-inteligencia
A12: exercito | C12: forcas_armadas | D12: rdf:type | E12: entity | L12: =C12 & "-" & E12 -> forcas_armadas-entity | M12: =C12 & "-" & D12 & "-" & E12 -> forcas_armadas-rdf:type-entity
A13: forca_aerea | C13: marinha | D13: rdfs:subClassOf | E13: forcas_armadas | L13: =C13 & "-" & E13 -> marinha-forcas_armadas | M13: =C13 & "-" & D13 & "-" & E13 -> marinha-rdfs:subClassOf-forcas_armadas
A14: forca_componente | C14: exercito | D14: rdfs:subClassOf | E14: forcas_armadas | L14: =C14 & "-" & E14 -> exercito-forcas_armadas | M14: =C14 & "-" & D14 & "-" & E14 -> exercito-rdfs:subClassOf-forcas_armadas
A15: forca_naval | C15: aeronautica | D15: rdfs:subClassOf | E15: forcas_armadas | L15: =C15 & "-" & E15 -> aeronautica-forcas_armadas | M15: =C15 & "-" & D15 & "-" & E15 -> aeronautica-rdfs:subClassOf-forcas_armadas
A16: forca_terrestre | C16: forcas_armadas | D16: c2rm:applied_to | E16: defesa_da_patria | L16: =C16 & "-" & E16 -> forcas_armadas-defesa_da_patria | M16: =C16 & "-" & D16 & "-" & E16 -> forcas_armadas-c2rm:applied_to-defesa_da_patria
A17: forcas_armadas | C17: forcas_componentes | D17: rdf:type | E17: entity | L17: =C17 & "-" & E17 -> forcas_componentes-entity | M17: =C17 & "-" & D17 & "-" & E17 -> forcas_componentes-rdf:type-entity
A18: heterogeneidade_dos_processos_de_emprego | C18: forca_naval | D18: rdfs:subClassOf | E18: forcas_componentes | L18: =C18 & "-" & E18 -> forca_naval-forcas_componentes | M18: =C18 & "-" & D18 & "-" & E18 -> forca_naval-rdfs:subClassOf-forcas_componentes
A19: inteligencia | C19: forca_terrestre | D19: rdfs:subClassOf | E19: forcas_componentes | L19: =C19 & "-" & E19 -> forca_terrestre-forcas_componentes | M19: =C19 & "-" & D19 & "-" & E19 -> forca_terrestre-rdfs:subClassOf-forcas_componentes
A20: logistica | C20: forca_aerea | D20: rdfs:subClassOf | E20: forcas_componentes | L20: =C20 & "-" & E20 -> forca_aerea-forcas_componentes | M20: =C20 & "-" & D20 & "-" & E20 -> forca_aerea-rdfs:subClassOf-forcas_componentes
A21: marinha | C21: forca_aerea | D21: rdfs:seeAlso | E21: operacao | L21: =C21 & "-" & E21 -> forca_aerea-operacao | M21: =C21 & "-" & D21 & "-" & E21 -> forca_aerea-rdfs:seeAlso-operacao
... A30: tatico | C30: presidente_da_republica | D30: c2rm:responsible_for | E30: forcas_armadas | L30: =C30 & "-" & E30 -> presidente_da_republica-forcas_armadas | M30: =C30 & "-" & D30 & "-" & E30 -> presidente_da_republica-c2rm:responsible_for-forcas_armadas
C31: presidente_da_republica | D31: c2rm:responsible_for | E31: politico | L31: =C31 & "-" & E31 -> presidente_da_republica-politico | M31: =C31 & "-" & D31 & "-" & E31 -> presidente_da_republica-c2rm:responsible_for-politico
C32: presidente_da_republica | D32: c2rm:responsible_for | E32: objetivos_politicos | L32: =C32 & "-" & E32 -> presidente_da_republica-objetivos_politicos | M32: =C32 & "-" & D32 & "-" & E32 -> presidente_da_republica-c2rm:responsible_for-objetivos_politicos
C33: presidente_da_republica | D33: c2rm:responsible_for | E33: comando_supremo | L33: =C33 & "-" & E33 -> presidente_da_republica-comando_supremo | M33: =C33 & "-" & D33 & "-" & E33 -> presidente_da_republica-c2rm:responsible_for-comando_supremo
C34: comando_supremo | D34: c2rm:responsible_for | E34: emprego | L34: =C34 & "-" & E34 -> comando_supremo-emprego | M34: =C34 & "-" & D34 & "-" & E34 -> comando_supremo-c2rm:responsible_for-emprego
C35: politico | D35: rdfs:seeAlso | E35: emprego | L35: =C35 & "-" & E35 -> politico-emprego | M35: =C35 & "-" & D35 & "-" & E35 -> politico-rdfs:seeAlso-emprego
C36: comandante_supremo | D36: c2rm:responsible_for | E36: politico | L36: =C36 & "-" & E36 -> comandante_supremo-politico | M36: =C36 & "-" & D36 & "-" & E36 -> comandante_supremo-c2rm:responsible_for-politico
C37: comandante_supremo | D37: owl:equivalentClass | E37: comando_supremo | L37: =C37 & "-" & E37 -> comandante_supremo-comando_supremo | M37: =C37 & "-" & D37 & "-" & E37 -> comandante_supremo-owl:equivalentClass-comando_supremo
C38: forca_componente | D38: c2rm:responsible_for | E38: operacao_conjunta | L38: =C38 & "-" & E38 -> forca_componente-operacao_conjunta | M38: =C38 & "-" & D38 & "-" & E38 -> forca_componente-c2rm:responsible_for-operacao_conjunta
C39: forcas_armadas | D39: rdfs:seeAlso | E39: operacao_conjunta | L39: =C39 & "-" & E39 -> forcas_armadas-operacao_conjunta | M39: =C39 & "-" & D39 & "-" & E39 -> forcas_armadas-rdfs:seeAlso-operacao_conjunta
C40: operacao_conjunta | D40: rdfs:comment | E40: heterogeneidade_dos_processos_de_emeprego | L40: =C40 & "-" & E40 -> operacao_conjunta-heterogeneidade_dos_processos_de_emeprego | M40: =C40 & "-" & D40 & "-" & E40 -> operacao_conjunta-rdfs:comment-heterogeneidade_dos_processos_de_emeprego
C41: forca_aerea | D41: rdfs:seeAlso | E41: emprego | L41: =C41 & "-" & E41 -> forca_aerea-emprego | M41: =C41 & "-" & D41 & "-" & E41 -> forca_aerea-rdfs:seeAlso-emprego
C42: tatico | D42: rdfs:seeAlso | E42: inteligencia
C43: comandante_supremo | D43: c2rm:responsible_for | E43: forcas_armadas
C44: comandante_supremo | D44: c2rm:responsible_for | E44: politico
C45: comandante_supremo | D45: c2rm:responsible_for | E45: objetivos_politicos
C46: comandante_supremo | D46: c2rm:responsible_for | E46: comando_supremo

Sheet MODELAGEM_1
A1: ATIVIDADE 1: Mapear entidades | D1: ATIVIDADE 3: Mapear triplas (ME x MR)
A2: Entidades de MC(Ei) | B2: Entidades de KG(Ek) | D2: Sujeito MC (Ei_1) | E2: Predicado KG (Rj) | F2: Objeto MC (Ei_2) | J2: RELAÇÕES | Y2: ENTIDADES_GRAFO
A3: ar | B3: aeronautica | D3: politico | E3: especialization | F3: nivel | J3: rdf:type | M3: N. ELEM {A} | N3: N. ELEM {B} | O3: TP | P3: TN | Q3: FN | R3: FP | S3: ACERTOS | T3: ERROS | U3: PRECISÃO | V3: COBERTURA | W3: ACURÁCIA | Y3: aeronautica
A4: c_log | D4: estrat | E4: especialization | F4: nivel | K4: B | L4: ENTIDADES | M4: =GRAFO!J2 -> 29 | N4: =COUNTA(A3:A30) -> 28 | O4: =COUNTIF(B3:B29,"<>"&"") -> 16 | P4: =N4-R4 -> 16 | Q4: =M4-O4 -> 13 | R4: =N4-O4 -> 12 | S4: =O4+P4 -> 32 | T4: =Q4+R4 -> 25 | U4: =O4/(O4+R4) -> 0.57142857 | V4: =O4/(O4+Q4) -> 0.55172414 | W4: =(O4+P4)/(O4+P4+Q4+R4) -> 0.56140351 | X4: =AVERAGE(U4:W4) -> 0.56151874 | Y4: comandante_supremo
A5: c2 | D5: op | E5: especialization | F5: nivel | L5: RELAÇÕES (SR) | M5: =GRAFO!J3 -> 41 | N5: =COUNTA(D35:D64) -> 30 | O5: =COUNTIF(M35:M64,"=1") -> 9 | P5: =N5-R5 -> 9 | Q5: =M5-O5 -> 32 | R5: =N5-O5 -> 21 | S5: =O5+P5 -> 18 | T5: =Q5+R5 -> 53 | U5: =O5/(O5+R5) -> 0.3 | V5: =O5/(O5+Q5) -> 0.2195122 | W5: =(O5+P5)/(O5+P5+Q5+R5) -> 0.25352113 | X5: =AVERAGE(U5:W5) -> 0.25767777 | Y5: comando_e_controle
A6: cmte | D6: tatico | E6: especialization | F6: nivel | L6: RELAÇÕES (CR) | M6: 41 | N6: =COUNTA(D35:D64) -> 30 | O6: =COUNTIF(U35:U64,"=1") -> 8 | P6: =N6-R6 -> 8 | Q6: =M6-O6 -> 33 | R6: =N6-O6 -> 22 | S6: =O6+P6 -> 16 | T6: =Q6+R6 -> 55 | U6: =O6/(O6+R6) -> 0.26666667 | V6: =O6/(O6+Q6) -> 0.19512195 | W6: =(O6+P6)/(O6+P6+Q6+R6) -> 0.22535211 | X6: =AVERAGE(U6:W6) -> 0.22904691 | Y6: comando_supremo
A7: comando_operacional | B7: comandos_operacionais | D7: plano | E7: especialization | F7: documento | X7: =AVERAGE(X4:X6) -> 0.34941447 | Y7: comandos_operacionais
A8: defesa_antiaerea | D8: diretriz | E8: especialization | F8: documento | Y8: defesa_da_patria
A9: diretriz | D9: objetivo | E9: especialization | F9: documento | K9: A | L9: A_E (GRAFO) | N9: =GRAFO!J2 -> 29 | Y9: emprego
A10: documento | D10: ordens | E10: especialization | F10: documento | K10: B | L10: B_E (M1) | N10: =N4 -> 28 | Y10: entity
A11: eb | B11: exercito | D11: op_cj | E11: especialization | F11: op_mil | K11: TP | L11: (A INT B) | N11: 16 | Y11: estrategico
A12: estrat | B12: estrategico | D12: mb | E12: especialization | F12: fa | K12: FN | L12: A-(A INT B) | M12: A-TP | N12: =N9-N11 -> 13 | Y12: estruturas
A13: estrutura_cmd | D13: eb | E13: especialization | F13: fa | K13: FP | L13: B-(A INT B) | M13: B-TP | Y13: exercito
A14: fa | B14: forcas_armadas | D14: fab | E14: especialization | F14: fa | K14: TN | M14: B-FP | Y14: forca_aerea
A15: fab | B15: aeronautica | D15: defesa_antiaerea | E15: especialization | F15: comando_operacional | K15: P | M15: VP/(VP+FP) | Y15: forca_componente
A16: fcte | B16: forca_componente | D16: inteligencia | E16: especialization | F16: comando_operacional | K16: R | M16: VP/(VP+FN) | Y16: forca_naval
A17: inteligencia | B17: inteligencia | D17: c2 | E17: especialization | F17: comando_operacional | K17: F1 | M17: (2 X P X C) / (P+C) | Y17: forca_terrestre
A18: mb | B18: marinha | D18: c_log | E18: especialization | F18: comando_operacional | K18: ACERTOS | M18: VP+VN | Y18: forcas_armadas
A19: md | D19: ar | E19: associado_com | F19: comando_operacional | K19: ERROS | M19: FP+FN | Y19: heterogeneidade_dos_processos_de_emeprego
A20: meios | D20: fa | E20: especialization | F20: estrutura_cmd | K20: ACURACIA | M20: (VP+VN)/(VP+FN+VN+FP) | Y20: inteligencia
A21: nivel | B21: nivel | D21: md | E21: especialization | F21: estrutura_cmd | Y21: logistica
A22: objetivo | B22: objetivos_politicos | D22: pr | E22: especialization | F22: estrutura_cmd | Y22: marinha
A23: op | B23: operacional | D23: fcte | E23: associado_com | F23: op_cj | Y23: nivel
A24: op_cj | B24: operacao_conjunta | D24: cmte | E24: comanda | F24: estrutura_cmd | Y24: objetivos_politicos
A25: op_mil | B25: operacao | D25: meios | E25: emprega | F25: comando_operacional | Y25: operacao
A26: ordens | D26: fcte | E26: composta_por | F26: fa | Y26: operacao_conjunta
A27: plano | D27: comando_operacional | E27: composta_por | F27: fcte | Y27: operacional
A28: politico | B28: politico | D28: estrutura_cmd | E28: elabora | F28: documento | Y28: peculiaridades_tecnico_profissional
A29: pr | B29: presidente_da_republica | D29: estrutura_cmd | E29: pertence | F29: nivel | Y29: politico
A30: tatico | B30: tatico | D30: md | E30: identifica | F30: meios | Y30: presidente_da_republica
D31: md | E31: identifica | F31: ar | Y31: tatico
D32: comando_operacional | E32: associado_com | F32: ar
A33: ATIVIDADE 2: Mapear relações | D33: ATIVIDADE 4: Relacionar triplas (MC x KG) | I33: ATIVIDADE 5: Validar pares de entidades nas triplas | O33: ATIVIDADE 6: Validar triplas completas (Ei_1, Rj x Ei_2)
A34: Relação de MC(Ri) | B34: Relação de KG(Rj) | D34: Sujeito MC (Ei_1) | E34: Predicado KG (Rj) | F34: Objeto MC (Ei_2) | G34: Achou? | I34: Pares de entidades (Ei_1, Ei_2) | L34: Se o par (Ei_1 e Ei_2) Existe no Par_de_ Lista_Entidades_do_KG | O34: Tripla (Ei_1, Rj, Ei_2) | T34: Se Tripla Existe nas Triplas do KG
A35: =E18 -> especialization | B35: rdfs:subClassOf | C35: =IF(INDEX($A$3:$B$30,MATCH(D3,$A$3:$A$30,0),2)<>0,"OK","NOK") -> OK | D35: =IF(INDEX($A$3:$B$30,MATCH(D3,$A$3:$A$30,0),2)<>0,INDEX($A$3:$B$30,MATCH(D3,$A$3:$A$30,0),2),D3) -> politico | E35: =IF(INDEX($A$35:$B$42,MATCH(E3,$A$35:$A$42,0),2)<>0,INDEX($A$35:$B$42,MATCH(E3,$A$35:$A$42,0),2),E3) -> rdfs:subClassOf | F35: =IF(INDEX($A$3:$B$30,MATCH(F3,$A$3:$A$30,0),2)<>0,INDEX($A$3:$B$30,MATCH(F3,$A$3:$A$30,0),2),F3) -> nivel | G35: =IF(INDEX($A$3:$B$30,MATCH(F3,$A$3:$A$30,0),2)<>0,"OK","NOK") -> OK | H35: =COUNTIFS(GRAFO!C2:C42,"=D34",GRAFO!E2:E42,"=F34") -> 0 | I35: =D35 &"-"&F35 -> politico-nivel | L35: =IF(INDEX(GRAFO!$L$2:'GRAFO'!$L$41,MATCH(I35,GRAFO!$L$2:'GRAFO'!$L$41,0),1)<>0,1,0) -> 1 | M35: =IFERROR(L35,0) -> 1 | O35: =D35 & "-" & E35 & "-" & F35 -> politico-rdfs:subClassOf-nivel | T35: =IF(INDEX(GRAFO!$M$2:'GRAFO'!$M$41,MATCH(O35,GRAFO!$M$2:'GRAFO'!$M$41,0),1)<>0,1,0) -> 1 | U35: =IFERROR(T35,0) -> 1
A36: =E23 -> associado_com | B36: rdfs:seeAlso | C36: =IF(INDEX($A$3:$B$30,MATCH(D4,$A$3:$A$30,0),2)<>0,"OK","NOK") -> OK | D36: =IF(INDEX($A$3:$B$30,MATCH(D4,$A$3:$A$30,0),2)<>0,INDEX($A$3:$B$30,MATCH(D4,$A$3:$A$30,0),2),D4) -> estrategico | E36: =IF(INDEX($A$35:$B$42,MATCH(E4,$A$35:$A$42,0),2)<>0,INDEX($A$35:$B$42,MATCH(E4,$A$35:$A$42,0),2),E4) -> rdfs:subClassOf | F36: =IF(INDEX($A$3:$B$30,MATCH(F4,$A$3:$A$30,0),2)<>0,INDEX($A$3:$B$30,MATCH(F4,$A$3:$A$30,0),2),F4) -> nivel | G36: =IF(INDEX($A$3:$B$30,MATCH(F4,$A$3:$A$30,0),2)<>0,"OK","NOK") -> OK | I36: =D36 &"-"&F36 -> estrategico-nivel | L36: =IF(INDEX(GRAFO!$L$2:'GRAFO'!$L$41,MATCH(I36,GRAFO!$L$2:'GRAFO'!$L$41,0),1)<>0,1,0) -> 1 | M36: =IFERROR(L36,0) -> 1 | O36: =D36 & "-" & E36 & "-" & F36 -> estrategico-rdfs:subClassOf-nivel | T36: =IF(INDEX(GRAFO!$M$2:'GRAFO'!$M$41,MATCH(O36,GRAFO!$M$2:'GRAFO'!$M$41,0),1)<>0,1,0) -> 1 | U36: =IFERROR(T36,0) -> 1
A37: =E24 -> comanda | B37: c2rm:responsible_for | C37: =IF(INDEX($A$3:$B$30,MATCH(D5,$A$3:$A$30,0),2)<>0,"OK","NOK") -> OK | D37: =IF(INDEX($A$3:$B$30,MATCH(D5,$A$3:$A$30,0),2)<>0,INDEX($A$3:$B$30,MATCH(D5,$A$3:$A$30,0),2),D5) -> operacional | E37: =IF(INDEX($A$35:$B$42,MATCH(E5,$A$35:$A$42,0),2)<>0,INDEX($A$35:$B$42,MATCH(E5,$A$35:$A$42,0),2),E5) -> rdfs:subClassOf | F37: =IF(INDEX($A$3:$B$30,MATCH(F5,$A$3:$A$30,0),2)<>0,INDEX($A$3:$B$30,MATCH(F5,$A$3:$A$30,0),2),F5) -> nivel | G37: =IF(INDEX($A$3:$B$30,MATCH(F5,$A$3:$A$30,0),2)<>0,"OK","NOK") -> OK | I37: =D37 &"-"&F37 -> operacional-nivel | L37: =IF(INDEX(GRAFO!$L$2:'GRAFO'!$L$41,MATCH(I37,GRAFO!$L$2:'GRAFO'!$L$41,0),1)<>0,1,0) -> 1 | M37: =IFERROR(L37,0) -> 1 | O37: =D37 & "-" & E37 & "-" & F37 -> operacional-rdfs:subClassOf-nivel | T37: =IF(INDEX(GRAFO!$M$2:'GRAFO'!$M$41,MATCH(O37,GRAFO!$M$2:'GRAFO'!$M$41,0),1)<>0,1,0) -> 1 | U37: =IFERROR(T37,0) -> 1
A38: =E26 -> composta_por | B38: rdfs:Bag | C38: =IF(INDEX($A$3:$B$30,MATCH(D6,$A$3:$A$30,0),2)<>0,"OK","NOK") -> OK | D38: =IF(INDEX($A$3:$B$30,MATCH(D6,$A$3:$A$30,0),2)<>0,INDEX($A$3:$B$30,MATCH(D6,$A$3:$A$30,0),2),D6) -> tatico | E38: =IF(INDEX($A$35:$B$42,MATCH(E6,$A$35:$A$42,0),2)<>0,INDEX($A$35:$B$42,MATCH(E6,$A$35:$A$42,0),2),E6) -> rdfs:subClassOf | F38: =IF(INDEX($A$3:$B$30,MATCH(F6,$A$3:$A$30,0),2)<>0,INDEX($A$3:$B$30,MATCH(F6,$A$3:$A$30,0),2),F6) -> nivel | G38: =IF(INDEX($A$3:$B$30,MATCH(F6,$A$3:$A$30,0),2)<>0,"OK","NOK") -> OK | I38: =D38 &"-"&F38 -> tatico-nivel | L38: =IF(INDEX(GRAFO!$L$2:'GRAFO'!$L$41,MATCH(I38,GRAFO!$L$2:'GRAFO'!$L$41,0),1)<>0,1,0) -> 1 | M38: =IFERROR(L38,0) -> 1 | O38: =D38 & "-" & E38 & "-" & F38 -> tatico-rdfs:subClassOf-nivel | T38: =IF(INDEX(GRAFO!$M$2:'GRAFO'!$M$41,MATCH(O38,GRAFO!$M$2:'GRAFO'!$M$41,0),1)<>0,1,0) -> 1 | U38: =IFERROR(T38,0) -> 1
A39: =E28 -> elabora | B39: c2rm:responsible_for | C39: =IF(INDEX($A$3:$B$30,MATCH(D7,$A$3:$A$30,0),2)<>0,"OK","NOK") -> NOK | D39: =IF(INDEX($A$3:$B$30,MATCH(D7,$A$3:$A$30,0),2)<>0,INDEX($A$3:$B$30,MATCH(D7,$A$3:$A$30,0),2),D7) -> plano | E39: =IF(INDEX($A$35:$B$42,MATCH(E7,$A$35:$A$42,0),2)<>0,INDEX($A$35:$B$42,MATCH(E7,$A$35:$A$42,0),2),E7) -> rdfs:subClassOf | F39: =IF(INDEX($A$3:$B$30,MATCH(F7,$A$3:$A$30,0),2)<>0,INDEX($A$3:$B$30,MATCH(F7,$A$3:$A$30,0),2),F7) -> documento | G39: =IF(INDEX($A$3:$B$30,MATCH(F7,$A$3:$A$30,0),2)<>0,"OK","NOK") -> NOK | I39: =D39 &"-"&F39 -> plano-documento | L39: =IF(INDEX(GRAFO!$L$2:'GRAFO'!$L$41,MATCH(I39,GRAFO!$L$2:'GRAFO'!$L$41,0),1)<>0,1,0) -> #N/A | M39: =IFERROR(L39,0) -> 0 | O39: =D39 & "-" & E39 & "-" & F39 -> plano-rdfs:subClassOf-documento | T39: =IF(INDEX(GRAFO!$M$2:'GRAFO'!$M$41,MATCH(O39,GRAFO!$M$2:'GRAFO'!$M$41,0),1)<>0,1,0) -> #N/A | U39: =IFERROR(T39,0) -> 0
A40: =E25 -> emprega | B40: c2rm:applied_to | C40: =IF(INDEX($A$3:$B$30,MATCH(D8,$A$3:$A$30,0),2)<>0,"OK","NOK") -> NOK | D40: =IF(INDEX($A$3:$B$30,MATCH(D8,$A$3:$A$30,0),2)<>0,INDEX($A$3:$B$30,MATCH(D8,$A$3:$A$30,0),2),D8) -> diretriz | E40: =IF(INDEX($A$35:$B$42,MATCH(E8,$A$35:$A$42,0),2)<>0,INDEX($A$35:$B$42,MATCH(E8,$A$35:$A$42,0),2),E8) -> rdfs:subClassOf | F40: =IF(INDEX($A$3:$B$30,MATCH(F8,$A$3:$A$30,0),2)<>0,INDEX($A$3:$B$30,MATCH(F8,$A$3:$A$30,0),2),F8) -> documento | G40: =IF(INDEX($A$3:$B$30,MATCH(F8,$A$3:$A$30,0),2)<>0,"OK","NOK") -> NOK | I40: =D40 &"-"&F40 -> diretriz-documento | L40: =IF(INDEX(GRAFO!$L$2:'GRAFO'!$L$41,MATCH(I40,GRAFO!$L$2:'GRAFO'!$L$41,0),1)<>0,1,0) -> #N/A | M40: =IFERROR(L40,0) -> 0 | O40: =D40 & "-" & E40 & "-" & F40 -> diretriz-rdfs:subClassOf-documento | T40: =IF(INDEX(GRAFO!$M$2:'GRAFO'!$M$41,MATCH(O40,GRAFO!$M$2:'GRAFO'!$M$41,0),1)<>0,1,0) -> #N/A | U40: =IFERROR(T40,0) -> 0
...

Sheet MODELAGEM_2
A1: ATIVIDADE 1: Mapear entidades | D1: ATIVIDADE 3: Mapear triplas (ME x MR)
A2: Entidades de MC(Ei) | B2: Entidades de KG(Ek) | D2: Sujeito MC (Ei_1) | E2: Predicado KG (Rj) | F2: Objeto MC (Ei_2) | J2: RELAÇÕES | Y2: ENTIDADES_GRAFO
A3: area de operações | D3: político | E3: instance_of | F3: nível | J3: rdf:type | M3: N. ELEM {A} | N3: N. ELEM {B} | O3: TP | P3: TN | Q3: FN | R3: FP | S3: ACERTOS | T3: ERROS | U3: PRECISÃO | V3: COBERTURA | W3: ACURÁCIA | Y3: aeronautica
A4: área de responsabilidade | D4: estratégico | E4: instance_of | F4: nível | K4: B | L4: ENTIDADES | M4: =GRAFO!J2 -> 29 | N4: =COUNTA(A3:A36) -> 34 | O4: =COUNTIF(B3:B29,"<>"&"") -> 8 | P4: =N4-R4 -> 8 | Q4: =M4-O4 -> 21 | R4: =N4-O4 -> 26 | S4: =O4+P4 -> 16 | T4: =Q4+R4 -> 47 | U4: =O4/(O4+R4) -> 0.23529412 | V4: =O4/(O4+Q4) -> 0.27586207 | W4: =(O4+P4)/(O4+P4+Q4+R4) -> 0.25396825 | X4: =AVERAGE(U4:W4) -> 0.25504148 | Y4: comandante_supremo
A5: ativa | D5: operacional | E5: instance_of | F5: nível | L5: RELAÇÕES (SR) | M5: =GRAFO!J3 -> 41 | N5: =COUNTA(D40:D65) -> 26 | O5: =COUNTIF(M40:M65,"=1") -> 4 | P5: =N5-R5 -> 4 | Q5: =M5-O5 -> 37 | R5: =N5-O5 -> 22 | S5: =O5+P5 -> 8 | T5: =Q5+R5 -> 59 | U5: =O5/(O5+R5) -> 0.15384615 | V5: =O5/(O5+Q5) -> 0.097560976 | W5: =(O5+P5)/(O5+P5+Q5+R5) -> 0.11940299 | X5: =AVERAGE(U5:W5) -> 0.12360337 | Y5: comando_e_controle
A6: comandante operacional | D6: tático | E6: instance_of | F6: nível | L6: RELAÇÕES (CR) | M6: 41 | N6: =COUNTA(D40:D65) -> 26 | O6: =COUNTIF(U40:U65,"=1") -> 0 | P6: =N6-R6 -> 0 | Q6: =M6-O6 -> 41 | R6: =N6-O6 -> 26 | S6: =O6+P6 -> 0 | T6: =Q6+R6 -> 67 | U6: =O6/(O6+R6) -> 0 | V6: =O6/(O6+Q6) -> 0 | W6: =(O6+P6)/(O6+P6+Q6+R6) -> 0 | X6: =AVERAGE(U6:W6) -> 0 | Y6: comando_supremo
A7: comdabra | D7: ativa | E7: especialization | F7: defesa aeroespacial | X7: =AVERAGE(X4:X6) -> 0.12621495 | Y7: comandos_operacionais
A8: comitê | D8: passiva | E8: especialization | F8: defesa aeroespacial | Y8: defesa_da_patria
A9: defesa aeroespacial | D9: defesa aeroespacial | E9: composition | F9: area de operações | K9: A | L9: A_E (GRAFO) | N9: =GRAFO!J2 -> 29 | Y9: emprego
A10: diretriz | D10: area de operações | E10: especialization | F10: área de responsabilidade | K10: B | L10: B_E (M1) | N10: =N4 -> 34 | Y10: entity
A11: dmed | D11: comandante operacional | E11: especialization | F11: pessoa | K11: TP | L11: (A INT B) | N11: 16 | Y11: estrategico
A12: documento | D12: presidente | E12: especialization | F12: pessoa | K12: FN | L12: A-(A INT B) | M12: A-TP | N12: =N9-N11 -> 13 | Y12: estruturas
A13: dped | D13: comandante operacional | E13: planeja | F13: planejamento militar | K13: FP | L13: B-(A INT B) | M13: B-TP | Y13: exercito
A14: eb | B14: exercito | D14: md | E14: instance_of | F14: instituição | K14: TN | M14: B-FP | Y14: forca_aerea
A15: entidade | D15: comdabra | E15: instance_of | F15: comitê | K15: P | M15: VP/(VP+FP) | Y15: forca_componente
A16: estratégico | B16: estrategico | D16: comitê | E16: emprega | F16: defesa aeroespacial | K16: R | M16: VP/(VP+FN) | Y16: forca_naval
A17: fab | B17: aeronautica | D17: forças componentes | E17: responsavel_por | F17: plano tático | K17: F1 | M17: (2 X P X C) / (P+C) | Y17: forca_terrestre
A18: forças componentes | B18: forca_componente | D18: plano tático | E18: identifica | F18: área de responsabilidade | K18: ACERTOS | M18: VP+VN | Y18: forcas_armadas
A19: instituição | D19: plano tático | E19: especialization | F19: plano | K19: ERROS | M19: FP+FN | Y19: heterogeneidade_dos_processos_de_emeprego
A20: mb | B20: marinha | D20: plano operacional | E20: especialization | F20: plano | K20: ACURACIA | M20: (VP+VN)/(VP+FN+VN+FP) | Y20: inteligencia
A21: md | D21: plano estratégico | E21: especialization | F21: plano | Y21: logistica
A22: nível | B22: nivel | D22: plano estratégico | E22: baseia | F22: plano operacional | Y22: marinha
A23: objetivos estratégicos | D23: plano operacional | E23: norteia | F23: plano tático | Y23: nivel
A24: objetivos operacionais | D24: pessoa | E24: especialization | F24: entidade | Y24: objetivos_politicos
A25: operação conjunta | B25: operacao_conjunta | D25: mb | E25: instance_of | F25: forças componentes | Y25: operacao
A26: operacional | B26: operacional | D26: eb | E26: instance_of | F26: forças componentes | Y26: operacao_conjunta
A27: passiva | D27: fab | E27: instance_of | F27: forças componentes | Y27: operacional
A28: pessoa | D28: comitê | E28: composition | F28: forças componentes | Y28: peculiaridades_tecnico_profissional
A29: planejamento militar | Y29: politico
A30: plano | Y30: presidente_da_republica
A31: plano estratégico | Y31: tatico
A32: plano operacional
A33: plano tático
A34: político | B34: politico
A35: presidente | B35: presidente_da_republica
A36: tático | B36: tatico
A38: ATIVIDADE 2: Mapear relações | D38: ATIVIDADE 4: Relacionar triplas (MC x KG) | I38: ATIVIDADE 5: Validar pares de entidades nas triplas | O38: ATIVIDADE 6: Validar triplas completas (Ei_1, Rj x Ei_2)
A39: Relação de MC(Ri) | B39: Relação de KG(Rj) | D39: Sujeito MC (Ei_1) | E39: Predicado KG (Rj) | F39: Objeto MC (Ei_2) | G39: Achou? | I39: Pares de entidades (Ei_1, Ei_2) | L39: Se o par (Ei_1 e Ei_2) Existe no Par_de_ Lista_Entidades_do_KG | O39: Tripla (Ei_1, Rj, Ei_2) | T39: Se Tripla Existe nas Triplas do KG
A40: especialization | B40: rdfs:subClassOf | C40: =IF(INDEX($A$3:$B$36,MATCH(D3,$A$3:$A$36,0),2)<>0,"OK","NOK") -> OK | D40: =IF(INDEX($A$3:$B$36,MATCH(D3,$A$3:$A$36,0),2)<>0,INDEX($A$3:$B$36,MATCH(D3,$A$3:$A$36,0),2),D3) -> politico | E40: =IF(INDEX($A$40:$B$55,MATCH(E3,$A$40:$A$55,0),2)<>0,INDEX($A$40:$B$55,MATCH(E3,$A$40:$A$55,0),2),E3) -> rdf:type | F40: =IF(INDEX($A$3:$B$36,MATCH(F3,$A$3:$A$36,0),2)<>0,INDEX($A$3:$B$36,MATCH(F3,$A$3:$A$36,0),2),F3) -> nivel | G40: =IF(INDEX($A$3:$B$36,MATCH(F3,$A$3:$A$36,0),2)<>0,"OK","NOK") -> OK | H40: =COUNTIFS(GRAFO!C2:C42,"=D34",GRAFO!E2:E42,"=F34") -> 0 | I40: =D40 &"-"&F40 -> politico-nivel | L40: =IF(INDEX(GRAFO!$L$2:'GRAFO'!$L$41,MATCH(I40,GRAFO!$L$2:'GRAFO'!$L$41,0),1)<>0,1,0) -> 1 | M40: =IFERROR(L40,0) -> 1 | O40: =D40 & "-" & E40 & "-" & F40 -> politico-rdf:type-nivel | T40: =IF(INDEX(GRAFO!$M$2:'GRAFO'!$M$41,MATCH(O40,GRAFO!$M$2:'GRAFO'!$M$41,0),1)<>0,1,0) -> #N/A | U40: =IFERROR(T40,0) -> 0
A41: associado_com | B41: rdfs:seeAlso | C41: =IF(INDEX($A$3:$B$36,MATCH(D4,$A$3:$A$36,0),2)<>0,"OK","NOK") -> OK | D41: =IF(INDEX($A$3:$B$36,MATCH(D4,$A$3:$A$36,0),2)<>0,INDEX($A$3:$B$36,MATCH(D4,$A$3:$A$36,0),2),D4) -> estrategico | E41: =IF(INDEX($A$40:$B$55,MATCH(E4,$A$40:$A$55,0),2)<>0,INDEX($A$40:$B$55,MATCH(E4,$A$40:$A$55,0),2),E4) -> rdf:type | F41: =IF(INDEX($A$3:$B$36,MATCH(F4,$A$3:$A$36,0),2)<>0,INDEX($A$3:$B$36,MATCH(F4,$A$3:$A$36,0),2),F4) -> nivel | G41: =IF(INDEX($A$3:$B$36,MATCH(F4,$A$3:$A$36,0),2)<>0,"OK","NOK") -> OK | I41: =D41 &"-"&F41 -> estrategico-nivel | L41: =IF(VLOOKUP(I41,GRAFO!L3:L42,1,0)<>"",1,0) -> 1 | M41: =IFERROR(L41,0) -> 1 | O41: =D41 & "-" & E41 & "-" & F41 -> estrategico-rdf:type-nivel | T41: =IF(INDEX(GRAFO!$M$2:'GRAFO'!$M$41,MATCH(O41,GRAFO!$M$2:'GRAFO'!$M$41,0),1)<>0,1,0) -> #N/A | U41: =IFERROR(T41,0) -> 0
...

Sheet MODELAGEM_3
A1: ATIVIDADE 1: Mapear entidades | D1: ATIVIDADE 3: Mapear triplas (ME x MR)
A2: Entidades de MC(Ei) | B2: Entidades de KG(Ek) | D2: Sujeito MC (Ei_1) | E2: Predicado KG (Rj) | F2: Objeto MC (Ei_2) | J2: RELAÇÕES | Y2: ENTIDADES_GRAFO
A3: ffaa | B3: forcas_armadas | D3: eb | E3: especialization | F3: ffaa | J3: rdf:type | M3: N. ELEM {A} | N3: N. ELEM {B} | O3: TP | P3: TN | Q3: FN | R3: FP | S3: ACERTOS | T3: ERROS | U3: PRECISÃO | V3: COBERTURA | W3: ACURÁCIA | Y3: aeronautica
A4: eb | B4: exercito | D4: mb | E4: especialization | F4: ffaa | K4: B | L4: ENTIDADES | M4: =GRAFO!J2 -> 29 | N4: =COUNTA(A3:A17) -> 15 | O4: =COUNTIF(B3:B17,"<>"&"") -> 9 | P4: =N4-R4 -> 9 | Q4: =M4-O4 -> 20 | R4: =N4-O4 -> 6 | S4: =O4+P4 -> 18 | T4: =Q4+R4 -> 26 | U4: =O4/(O4+R4) -> 0.6 | V4: =O4/(O4+Q4) -> 0.31034483 | W4: =(O4+P4)/(O4+P4+Q4+R4) -> 0.40909091 | X4: =AVERAGE(U4:W4) -> 0.43981191 | Y4: comandante_supremo
A5: mb | B5: marinha | D5: fab | E5: especialization | F5: ffaa | L5: RELAÇÕES (SR) | M5: =GRAFO!J3 -> 41 | N5: =COUNTA(D40:D49) -> 10 | O5: =COUNTIF(M40:M49,"=1") -> 4 | P5: =N5-R5 -> 4 | Q5: =M5-O5 -> 37 | R5: =N5-O5 -> 6 | S5: =O5+P5 -> 8 | T5: =Q5+R5 -> 43 | U5: =O5/(O5+R5) -> 0.4 | V5: =O5/(O5+Q5) -> 0.097560976 | W5: =(O5+P5)/(O5+P5+Q5+R5) -> 0.15686275 | X5: =AVERAGE(U5:W5) -> 0.21814124 | Y5: comando_e_controle
A6: fab | B6: aeronautica | D6: op_mil_simples | E6: especialization | F6: op_mil | L6: RELAÇÕES (CR) | M6: 41 | N6: =COUNTA(D40:D49) -> 10 | O6: =COUNTIF(U40:U49,"=1") -> 4 | P6: =N6-R6 -> 4 | Q6: =M6-O6 -> 37 | R6: =N6-O6 -> 6 | S6: =O6+P6 -> 8 | T6: =Q6+R6 -> 43 | U6: =O6/(O6+R6) -> 0.4 | V6: =O6/(O6+Q6) -> 0.097560976 | W6: =(O6+P6)/(O6+P6+Q6+R6) -> 0.15686275 | X6: =AVERAGE(U6:W6) -> 0.21814124 | Y6: comando_supremo
A7: op_mil | B7: operacao | D7: op_mil_conj | E7: especialization | F7: op_mil | X7: =AVERAGE(X4:X6) -> 0.29203146 | Y7: comandos_operacionais
A8: op_mil_simples | D8: op_mil | E8: composition | F8: op_mil_conj | Y8: defesa_da_patria
A9: op_mil_conj | B9: operacao_conjunta | D9: pr | E9: associado_com | F9: dpen | K9: A | L9: A_E (GRAFO) | N9: =GRAFO!J2 -> 29 | Y9: emprego
A10: pr | B10: presidente_da_republica | D10: md | E10: associado_com | F10: plano_estrategico | K10: B | L10: B_E (M1) | N10: =N4 -> 15 | Y10: entity
A11: dpen | D11: fcte | E11: associado_com | F11: plano_tatico | K11: TP | L11: (A INT B) | N11: 16 | Y11: estrategico
A12: md | D12: comando_operacional | E12: associado_com | F12: plano_operacional | K12: FN | L12: A-(A INT B) | M12: A-TP | N12: =N9-N11 -> 13 | Y12: estruturas
A13: plano_estrategico | K13: FP | L13: B-(A INT B) | M13: B-TP | Y13: exercito
A14: fcte | B14: forca_componente | K14: TN | M14: B-FP | Y14: forca_aerea
A15: plano_tatico | K15: P | M15: VP/(VP+FP) | Y15: forca_componente
A16: comando_operacional | B16: comandos_operacionais | K16: R | M16: VP/(VP+FN) | Y16: forca_naval
A17: plano_operacional | K17: F1 | M17: (2 X P X C) / (P+C) | Y17: forca_terrestre
K18: ACERTOS | M18: VP+VN | Y18: forcas_armadas
K19: ERROS | M19: FP+FN | Y19: heterogeneidade_dos_processos_de_emeprego
K20: ACURACIA | M20: (VP+VN)/(VP+FN+VN+FP) | Y20: inteligencia
Y21: logistica
Y22: marinha
Y23: nivel
Y24: objetivos_politicos
Y25: operacao
Y26: operacao_conjunta
Y27: operacional
Y28: peculiaridades_tecnico_profissional
Y29: politico
Y30: presidente_da_republica
Y31: tatico
A38: ATIVIDADE 2: Mapear relações | D38: ATIVIDADE 4: Relacionar triplas (MC x KG) | I38: ATIVIDADE 5: Validar pares de entidades nas triplas | O38: ATIVIDADE 6: Validar triplas completas (Ei_1, Rj x Ei_2)
A39: Relação de MC(Ri) | B39: Relação de KG(Rj) | D39: Sujeito MC (Ei_1) | E39: Predicado KG (Rj) | F39: Objeto MC (Ei_2) | G39: Achou? | I39: Pares de entidades (Ei_1, Ei_2) | L39: Se o par (Ei_1 e Ei_2) Existe no Par_de_ Lista_Entidades_do_KG | O39: Tripla (Ei_1, Rj, Ei_2) | T39: Se Tripla Existe nas Triplas do KG
A40: especialization | B40: rdfs:subClassOf | C40: =IF(INDEX($A$3:$B$17,MATCH(D3,$A$3:$A$17,0),2)<>0,"OK","NOK") -> OK | D40: =IF(INDEX($A$3:$B$17,MATCH(D3,$A$3:$A$17,0),2)<>0,INDEX($A$3:$B$17,MATCH(D3,$A$3:$A$17,0),2),D3) -> exercito | E40: =IF(INDEX($A$40:$B$44,MATCH(E3,$A$40:$A$44,0),2)<>0,INDEX($A$40:$B$44,MATCH(E3,$A$40:$A$44,0),2),E3) -> rdfs:subClassOf | F40: =IF(INDEX($A$3:$B$17,MATCH(F3,$A$3:$A$17,0),2)<>0,INDEX($A$3:$B$17,MATCH(F3,$A$3:$A$17,0),2),F3) -> forcas_armadas | G40: =IF(INDEX($A$3:$B$36,MATCH(F3,$A$3:$A$36,0),2)<>0,"OK","NOK") -> OK | H40: =COUNTIFS(GRAFO!C2:C42,"=D34",GRAFO!E2:E42,"=F34") -> 0 | I40: =D40 &"-"&F40 -> exercito-forcas_armadas | L40: =IF(INDEX(GRAFO!$L$2:'GRAFO'!$L$41,MATCH(I40,GRAFO!$L$2:'GRAFO'!$L$41,0),1)<>0,1,0) -> 1 | M40: =IFERROR(L40,0) -> 1 | O40: =D40 & "-" & E40 & "-" & F40 -> exercito-rdfs:subClassOf-forcas_armadas | T40: =IF(INDEX(GRAFO!$M$2:'GRAFO'!$M$41,MATCH(O40,GRAFO!$M$2:'GRAFO'!$M$41,0),1)<>0,1,0) -> 1 | U40: =IFERROR(T40,0) -> 1
A41: associado_com | B41: rdfs:seeAlso | C41: =IF(INDEX($A$3:$B$17,MATCH(D4,$A$3:$A$17,0),2)<>0,"OK","NOK") -> OK | D41: =IF(INDEX($A$3:$B$17,MATCH(D4,$A$3:$A$17,0),2)<>0,INDEX($A$3:$B$17,MATCH(D4,$A$3:$A$17,0),2),D4) -> marinha | E41: =IF(INDEX($A$40:$B$44,MATCH(E4,$A$40:$A$44,0),2)<>0,INDEX($A$40:$B$44,MATCH(E4,$A$40:$A$44,0),2),E4) -> rdfs:subClassOf | F41: =IF(INDEX($A$3:$B$17,MATCH(F4,$A$3:$A$17,0),2)<>0,INDEX($A$3:$B$17,MATCH(F4,$A$3:$A$17,0),2),F4) -> forcas_armadas | G41: =IF(INDEX($A$3:$B$36,MATCH(F4,$A$3:$A$36,0),2)<>0,"OK","NOK") -> OK | I41: =D41 &"-"&F41 -> marinha-forcas_armadas | L41: =IF(VLOOKUP(I41,GRAFO!L3:L42,1,0)<>"",1,0) -> 1 | M41: =IFERROR(L41,0) -> 1 | O41: =D41 & "-" & E41 & "-" & F41 -> marinha-rdfs:subClassOf-forcas_armadas | T41: =IF(INDEX(GRAFO!$M$2:'GRAFO'!$M$41,MATCH(O41,GRAFO!$M$2:'GRAFO'!$M$41,0),1)<>0,1,0) -> 1 | U41: =IFERROR(T41,0) -> 1
A42: responsavel_por | B42: c2rm:responsible_for | C42: =IF(INDEX($A$3:$B$17,MATCH(D5,$A$3:$A$17,0),2)<>0,"OK","NOK") -> OK | D42: =IF(INDEX($A$3:$B$17,MATCH(D5,$A$3:$A$17,0),2)<>0,INDEX($A$3:$B$17,MATCH(D5,$A$3:$A$17,0),2),D5) -> aeronautica | E42: =IF(INDEX($A$40:$B$44,MATCH(E5,$A$40:$A$44,0),2)<>0,INDEX($A$40:$B$44,MATCH(E5,$A$40:$A$44,0),2),E5) -> rdfs:subClassOf | F42: =IF(INDEX($A$3:$B$17,MATCH(F5,$A$3:$A$17,0),2)<>0,INDEX($A$3:$B$17,MATCH(F5,$A$3:$A$17,0),2),F5) -> forcas_armadas | G42: =IF(INDEX($A$3:$B$36,MATCH(F5,$A$3:$A$36,0),2)<>0,"OK","NOK") -> OK | I42: =D42 &"-"&F42 -> aeronautica-forcas_armadas | L42: =IF(VLOOKUP(I42,GRAFO!L4:L43,1,0)<>"",1,0) -> 1 | M42: =IFERROR(L42,0) -> 1 | O42: =D42 & "-" & E42 & "-" & F42 -> aeronautica-rdfs:subClassOf-forcas_armadas | T42: =IF(INDEX(GRAFO!$M$2:'GRAFO'!$M$41,MATCH(O42,GRAFO!$M$2:'GRAFO'!$M$41,0),1)<>0,1,0) -> 1 | U42: =IFERROR(T42,0) -> 1
A43: composition | B43: rdfs:Bag | C43: =IF(INDEX($A$3:$B$17,MATCH(D6,$A$3:$A$17,0),2)<>0,"OK","NOK") -> NOK | D43: =IF(INDEX($A$3:$B$17,MATCH(D6,$A$3:$A$17,0),2)<>0,INDEX($A$3:$B$17,MATCH(D6,$A$3:$A$17,0),2),D6) -> op_mil_simples | E43: =IF(INDEX($A$40:$B$44,MATCH(E6,$A$40:$A$44,0),2)<>0,INDEX($A$40:$B$44,MATCH(E6,$A$40:$A$44,0),2),E6) -> rdfs:subClassOf | F43: =IF(INDEX($A$3:$B$17,MATCH(F6,$A$3:$A$17,0),2)<>0,INDEX($A$3:$B$17,MATCH(F6,$A$3:$A$17,0),2),F6) -> operacao | G43: =IF(INDEX($A$3:$B$36,MATCH(F6,$A$3:$A$36,0),2)<>0,"OK","NOK") -> OK | I43: =D43 &"-"&F43 -> op_mil_simples-operacao | L43: =IF(VLOOKUP(I43,GRAFO!L5:L44,1,0)<>"",1,0) -> #N/A | M43: =IFERROR(L43,0) -> 0 | O43: =D43 & "-" & E43 & "-" & F43 -> op_mil_simples-rdfs:subClassOf-operacao | T43: =IF(INDEX(GRAFO!$M$2:'GRAFO'!$M$41,MATCH(O43,GRAFO!$M$2:'GRAFO'!$M$41,0),1)<>0,1,0) -> #N/A | U43: =IFERROR(T43,0) -> 0
A44: e_um | B44: rdfs:seeAlso | C44: =IF(INDEX($A$3:$B$17,MATCH(D7,$A$3:$A$17,0),2)<>0,"OK","NOK") -> OK | D44: =IF(INDEX($A$3:$B$17,MATCH(D7,$A$3:$A$17,0),2)<>0,INDEX($A$3:$B$17,MATCH(D7,$A$3:$A$17,0),2),D7) -> operacao_conjunta | E44: =IF(INDEX($A$40:$B$44,MATCH(E7,$A$40:$A$44,0),2)<>0,INDEX($A$40:$B$44,MATCH(E7,$A$40:$A$44,0),2),E7) -> rdfs:subClassOf | F44: =IF(INDEX($A$3:$B$17,MATCH(F7,$A$3:$A$17,0),2)<>0,INDEX($A$3:$B$17,MATCH(F7,$A$3:$A$17,0),2),F7) -> operacao | G44: =IF(INDEX($A$3:$B$36,MATCH(F7,$A$3:$A$36,0),2)<>0,"OK","NOK") -> OK | I44: =D44 &"-"&F44 -> operacao_conjunta-operacao | L44: =IF(VLOOKUP(I44,GRAFO!L6:L45,1,0)<>"",1,0) -> 1 | M44: =IFERROR(L44,0) -> 1 | O44: =D44 & "-" & E44 & "-" & F44 -> operacao_conjunta-rdfs:subClassOf-operacao | T44: =IF(INDEX(GRAFO!$M$2:'GRAFO'!$M$41,MATCH(O44,GRAFO!$M$2:'GRAFO'!$M$41,0),1)<>0,1,0) -> 1 | U44: =IFERROR(T44,0) -> 1
D45: =IF(INDEX($A$3:$B$17,MATCH(D8,$A$3:$A$17,0),2)<>0,INDEX($A$3:$B$17,MATCH(D8,$A$3:$A$17,0),2),D8) -> operacao | E45: =IF(INDEX($A$40:$B$44,MATCH(E8,$A$40:$A$44,0),2)<>0,INDEX($A$40:$B$44,MATCH(E8,$A$40:$A$44,0),2),E8) -> rdfs:Bag | F45: =IF(INDEX($A$3:$B$17,MATCH(F8,$A$3:$A$17,0),2)<>0,INDEX($A$3:$B$17,MATCH(F8,$A$3:$A$17,0),2),F8) -> operacao_conjunta | G45: =IF(INDEX($A$3:$B$36,MATCH(F8,$A$3:$A$36,0),2)<>0,"OK","NOK") -> OK | I45: =D45 &"-"&F45 -> operacao-operacao_conjunta | L45: =IF(VLOOKUP(I45,GRAFO!L7:L46,1,0)<>"",1,0) -> #N/A | M45: =IFERROR(L45,0) -> 0 | O45: =D45 & "-" & E45 & "-" & F45 -> operacao-rdfs:Bag-operacao_conjunta | T45: =IF(INDEX(GRAFO!$M$2:'GRAFO'!$M$41,MATCH(O45,GRAFO!$M$2:'GRAFO'!$M$41,0),1)<>0,1,0) -> #N/A | U45: =IFERROR(T45,0) -> 0
D46: =IF(INDEX($A$3:$B$17,MATCH(D9,$A$3:$A$17,0),2)<>0,INDEX($A$3:$B$17,MATCH(D9,$A$3:$A$17,0),2),D9) -> presidente_da_republica | E46: =IF(INDEX($A$40:$B$44,MATCH(E9,$A$40:$A$44,0),2)<>0,INDEX($A$40:$B$44,MATCH(E9,$A$40:$A$44,0),2),E9) -> rdfs:seeAlso | F46: =IF(INDEX($A$3:$B$17,MATCH(F9,$A$3:$A$17,0),2)<>0,INDEX($A$3:$B$17,MATCH(F9,$A$3:$A$17,0),2),F9) -> dpen | G46: =IF(INDEX($A$3:$B$36,MATCH(F9,$A$3:$A$36,0),2)<>0,"OK","NOK") -> NOK | I46: =D46 &"-"&F46 -> presidente_da_republica-dpen | L46: =IF(VLOOKUP(I46,GRAFO!L8:L47,1,0)<>"",1,0) -> #N/A | M46: =IFERROR(L46,0) -> 0 | O46: =D46 & "-" & E46 & "-" & F46 -> presidente_da_republica-rdfs:seeAlso-dpen | T46: =IF(INDEX(GRAFO!$M$2:'GRAFO'!$M$41,MATCH(O46,GRAFO!$M$2:'GRAFO'!$M$41,0),1)<>0,1,0) -> #N/A | U46: =IFERROR(T46,0) -> 0
...

Sheet MODELAGEM_4
A1: ATIVIDADE 1: Mapear entidades | D1: ATIVIDADE 3: Mapear triplas (ME x MR)
A2: Entidades de MC(Ei) | B2: Entidades de KG(Ek) | D2: Sujeito MC (Ei_1) | E2: Predicado KG (Rj) | F2: Objeto MC (Ei_2) | J2: RELAÇÕES | Y2: ENTIDADES_GRAFO | AC2: R1 | AD2: equivalent_to | AE2: owl:equivalentClass
A3: comando_supremo | B3: comandante_supremo | D3: comando_supremo | E3: estabelece | F3: objetivos_politicos | J3: rdf:type | M3: N. ELEM {A} | N3: N. ELEM {B} | O3: TP | P3: TN | Q3: FN | R3: FP | S3: ACERTOS | T3: ERROS | U3: PRECISÃO | V3: COBERTURA | W3: ACURÁCIA | Y3: aeronautica | AC3: R2 | AD3: associated_with | AE3: rdfs:seeAlso
A4: objetivos_politicos | B4: objetivos_politicos | D4: comando_supremo | E4: estabelece | F4: dped | K4: B | L4: ENTIDADES | M4: =GRAFO!J2 -> 29 | N4: =COUNTA(A3:A25) -> 23 | O4: =COUNTIF(B3:B25,"<>"&"") -> 12 | P4: =N4-R4 -> 12 | Q4: =M4-O4 -> 17 | R4: =N4-O4 -> 11 | S4: =O4+P4 -> 24 | T4: =Q4+R4 -> 28 | U4: =O4/(O4+R4) -> 0.52173913 | V4: =O4/(O4+Q4) -> 0.4137931 | W4: =(O4+P4)/(O4+P4+Q4+R4) -> 0.46153846 | X4: =AVERAGE(U4:W4) -> 0.46569023 | Y4: comandante_supremo | AC4: R3 | AD4: composed_of | AE4: rdf:Bag
A5: dped | D5: comando_supremo | E5: comanda | F5: md | L5: RELAÇÕES (SR) | M5: =GRAFO!J3 -> 41 | N5: =COUNTA(D40:D61) -> 22 | O5: =COUNTIF(M40:M61,"=1") -> 4 | P5: =N5-R5 -> 4 | Q5: =M5-O5 -> 37 | R5: =N5-O5 -> 18 | S5: =O5+P5 -> 8 | T5: =Q5+R5 -> 55 | U5: =O5/(O5+R5) -> 0.18181818 | V5: =O5/(O5+Q5) -> 0.097560976 | W5: =(O5+P5)/(O5+P5+Q5+R5) -> 0.12698413 | X5: =AVERAGE(U5:W5) -> 0.13545443 | Y5: comando_e_controle | AC5: R4 | AD5: type_of | AE5: rdfs:subClassOf
A6: md | D6: md | E6: estabelece | F6: dmed | L6: RELAÇÕES (CR) | M6: 41 | N6: =COUNTA(D40:D61) -> 22 | O6: =COUNTIF(U40:U61,"=1") -> 3 | P6: =N6-R6 -> 3 | Q6: =M6-O6 -> 38 | R6: =N6-O6 -> 19 | S6: =O6+P6 -> 6 | T6: =Q6+R6 -> 57 | U6: =O6/(O6+R6) -> 0.13636364 | V6: =O6/(O6+Q6) -> 0.073170732 | W6: =(O6+P6)/(O6+P6+Q6+R6) -> 0.095238095 | X6: =AVERAGE(U6:W6) -> 0.10159082 | Y6: comando_supremo | AC6: R5 | AD6: defined_by | AE6: rdfs:comment
A7: dmed | D7: comandos_operacionais | E7: gerencia | F7: op_conjunta | X7: =AVERAGE(X4:X6) -> 0.23424516 | Y7: comandos_operacionais | AC7: R6 | AD7: co-referenced | AE7: c2rm:coreferenced
A8: op_conjunta | B8: operacao_conjunta | D8: md | E8: comanda | F8: fa | Y8: defesa_da_patria | AC8: R7 | AD8: instance_of | AE8: rdf:type
A9: fa | B9: forcas_armadas | D9: fab | E9: especialization | F9: fa | K9: A | L9: A_E (GRAFO) | N9: =GRAFO!J2 -> 29 | Y9: emprego | AC9: R8 | AD9: responsible_for | AE9: c2rm:responsible_for
A10: fab | B10: aeronautica | D10: exerc | E10: especialization | F10: fa | K10: B | L10: B_E (M1) | N10: =N4 -> 23 | Y10: entity | AC10: R9 | AD10: capacity_of | AE10: c2rm:capacity_of
A11: exerc | B11: exercito | D11: marinha | E11: especialization | F11: fa | K11: TP | L11: (A INT B) | N11: 16 | Y11: estrategico | AC11: R10 | AD11: occurs_in | AE11: c2rm:occurs_in
A12: marinha | B12: marinha | D12: fa | E12: participa | F12: op_conjunta | K12: FN | L12: A-(A INT B) | M12: A-TP | N12: =N9-N11 -> 13 | Y12: estruturas | AC12: R11 | AD12: applied_to | AE12: c2rm:applied_to
A13: area_de_operacao | D13: op_conjunta | E13: participa | F13: planos_taticos | K13: FP | L13: B-(A INT B) | M13: B-TP | Y13: exercito
A14: comando_logistico | D14: ar_ai | E14: atua | F14: area_de_operacao | K14: TN | M14: B-FP | Y14: forca_aerea
A15: planos_taticos | D15: op_conjunta | E15: participa | F15: op_conjunta | K15: P | M15: VP/(VP+FP) | Y15: forca_componente
A16: força_componente | B16: forca_componente | D16: comando_logistico | E16: precisa | F16: planos_taticos | K16: R | M16: VP/(VP+FN) | Y16: forca_naval
A17: meios | D17: comando_logistico | E17: coordena | F17: area_de_operacao | K17: F1 | M17: (2 X P X C) / (P+C) | Y17: forca_terrestre
A18: força_terrestre | B18: forca_terrestre | D18: planos_taticos | E18: nortea | F18: planos_operacionais | K18: ACERTOS | M18: VP+VN | Y18: forcas_armadas
A19: força_naval | B19: forca_naval | D19: planos_operacionais | E19: produz | F19: op_conjunta | K19: ERROS | M19: FP+FN | Y19: heterogeneidade_dos_processos_de_emeprego
A20: planos_taticos | D20: força_componente | E20: executa | F20: planos_taticos | K20: ACURACIA | M20: (VP+VN)/(VP+FN+VN+FP) | Y20: inteligencia
A21: planos_operacionais | D21: força_terrestre | E21: especialization | F21: força_componente | Y21: logistica
A22: comando_logistico | D22: força_naval | E22: especialization | F22: força_componente | Y22: marinha
A23: comandos_operacionais | B23: comandos_operacionais | D23: comando_logistico | E23: coordena | F23: meios | Y23: nivel
A24: ar_ai | D24: fa | E24: realiza | F24: defesa_da_patria | Y24: objetivos_politicos
A25: defesa_da_patria | B25: defesa_da_patria | Y25: operacao
Y26: operacao_conjunta
Y27: operacional
Y28: peculiaridades_tecnico_profissional
Y29: politico
Y30: presidente_da_republica
Y31: tatico
A38: ATIVIDADE 2: Mapear relações | D38: ATIVIDADE 4: Relacionar triplas (MC x KG) | I38: ATIVIDADE 5: Validar pares de entidades nas triplas | O38: ATIVIDADE 6: Validar triplas completas (Ei_1, Rj x Ei_2)
A39: Relação de MC(Ri) | B39: Relação de KG(Rj) | D39: Sujeito MC (Ei_1) | E39: Predicado KG (Rj) | F39: Objeto MC (Ei_2) | G39: Achou? | I39: Pares de entidades (Ei_1, Ei_2) | L39: Se o par (Ei_1 e Ei_2) Existe no Par_de_ Lista_Entidades_do_KG | O39: Tripla (Ei_1, Rj, Ei_2) | T39: Se Tripla Existe nas Triplas do KG
A40: especialization | B40: rdfs:subClassOf | C40: =IF(INDEX($A$3:$B$24,MATCH(D3,$A$3:$A$24,0),2)<>0,"OK","NOK") -> OK | D40: =IF(INDEX($A$3:$B$25,MATCH(D3,$A$3:$A$25,0),2)<>0,INDEX($A$3:$B$25,MATCH(D3,$A$3:$A$25,0),2),D3) -> comandante_supremo | E40: =IF(INDEX($A$40:$B$58,MATCH(E3,$A$40:$A$58,0),2)<>0,INDEX($A$40:$B$58,MATCH(E3,$A$40:$A$58,0),2),E3) -> c2rm:applied_to | F40: =IF(INDEX($A$3:$B$25,MATCH(F3,$A$3:$A$25,0),2)<>0,INDEX($A$3:$B$25,MATCH(F3,$A$3:$A$25,0),2),F3) -> objetivos_politicos | G40: =IF(INDEX($A$3:$B$25,MATCH(F3,$A$3:$A$25,0),2)<>0,"OK","NOK") -> OK | H40: =COUNTIFS(GRAFO!C2:C42,"=D34",GRAFO!E2:E42,"=F34") -> 0 | I40: =D40 &"-"&F40 -> comandante_supremo-objetivos_politicos | L40: =IF(INDEX(GRAFO!$L$2:'GRAFO'!$L$41,MATCH(I40,GRAFO!$L$2:'GRAFO'!$L$41,0),1)<>0,1,0) -> #N/A | M40: =IFERROR(L40,0) -> 0 | O40: =D40 & "-" & E40 & "-" & F40 -> comandante_supremo-c2rm:applied_to-objetivos_politicos | T40: =IF(INDEX(GRAFO!$M$2:'GRAFO'!$M$41,MATCH(O40,GRAFO!$M$2:'GRAFO'!$M$41,0),1)<>0,1,0) -> #N/A | U40: =IFERROR(T40,0) -> 0
A41: associado_com | B41: rdfs:seeAlso | C41: =IF(INDEX($A$3:$B$24,MATCH(D4,$A$3:$A$24,0),2)<>0,"OK","NOK") -> OK | D41: =IF(INDEX($A$3:$B$25,MATCH(D4,$A$3:$A$25,0),2)<>0,INDEX($A$3:$B$25,MATCH(D4,$A$3:$A$25,0),2),D4) -> comandante_supremo | E41: =IF(INDEX($A$40:$B$58,MATCH(E4,$A$40:$A$58,0),2)<>0,INDEX($A$40:$B$58,MATCH(E4,$A$40:$A$58,0),2),E4) -> c2rm:applied_to | F41: =IF(INDEX($A$3:$B$25,MATCH(F4,$A$3:$A$25,0),2)<>0,INDEX($A$3:$B$25,MATCH(F4,$A$3:$A$25,0),2),F4) -> dped | G41: =IF(INDEX($A$3:$B$36,MATCH(F4,$A$3:$A$36,0),2)<>0,"OK","NOK") -> NOK | I41: =D41 &"-"&F41 -> comandante_supremo-dped | L41: =IF(VLOOKUP(I41,GRAFO!L3:L42,1,0)<>"",1,0) -> #N/A | M41: =IFERROR(L41,0) -> 0 | O41: =D41 & "-" & E41 & "-" & F41 -> comandante_supremo-c2rm:applied_to-dped | T41: =IF(INDEX(GRAFO!$M$2:'GRAFO'!$M$41,MATCH(O41,GRAFO!$M$2:'GRAFO'!$M$41,0),1)<>0,1,0) -> #N/A | U41: =IFERROR(T41,0) -> 0
A42: responsavel_por | B42: c2rm:responsible_for | C42: =IF(INDEX($A$3:$B$24,MATCH(D5,$A$3:$A$24,0),2)<>0,"OK","NOK") -> OK | D42: =IF(INDEX($A$3:$B$25,MATCH(D5,$A$3:$A$25,0),2)<>0,INDEX($A$3:$B$25,MATCH(D5,$A$3:$A$25,0),2),D5) -> comandante_supremo | E42: =IF(INDEX($A$40:$B$58,MATCH(E5,$A$40:$A$58,0),2)<>0,INDEX($A$40:$B$58,MATCH(E5,$A$40:$A$58,0),2),E5) -> c2rm:responsible_for | F42: =IF(INDEX($A$3:$B$25,MATCH(F5,$A$3:$A$25,0),2)<>0,INDEX($A$3:$B$25,MATCH(F5,$A$3:$A$25,0),2),F5) -> md | G42: =IF(INDEX($A$3:$B$36,MATCH(F5,$A$3:$A$36,0),2)<>0,"OK","NOK") -> NOK | I42: =D42 &"-"&F42 -> comandante_supremo-md | L42: =IF(VLOOKUP(I42,GRAFO!L4:L43,1,0)<>"",1,0) -> #N/A | M42: =IFERROR(L42,0) -> 0 | O42: =D42 & "-" & E42 & "-" & F42 -> comandante_supremo-c2rm:responsible_for-md | T42: =IF(INDEX(GRAFO!$M$2:'GRAFO'!$M$41,MATCH(O42,GRAFO!$M$2:'GRAFO'!$M$41,0),1)<>0,1,0) -> #N/A | U42: =IFERROR(T42,0) -> 0
A43: composition | B43: rdf:Bag | C43: =IF(INDEX($A$3:$B$24,MATCH(D6,$A$3:$A$24,0),2)<>0,"OK","NOK") -> NOK | D43: =IF(INDEX($A$3:$B$25,MATCH(D6,$A$3:$A$25,0),2)<>0,INDEX($A$3:$B$25,MATCH(D6,$A$3:$A$25,0),2),D6) -> md | E43: =IF(INDEX($A$40:$B$58,MATCH(E6,$A$40:$A$58,0),2)<>0,INDEX($A$40:$B$58,MATCH(E6,$A$40:$A$58,0),2),E6) -> c2rm:applied_to | F43: =IF(INDEX($A$3:$B$25,MATCH(F6,$A$3:$A$25,0),2)<>0,INDEX($A$3:$B$25,MATCH(F6,$A$3:$A$25,0),2),F6) -> dmed | G43: =IF(INDEX($A$3:$B$36,MATCH(F6,$A$3:$A$36,0),2)<>0,"OK","NOK") -> NOK | I43: =D43 &"-"&F43 -> md-dmed | L43: =IF(VLOOKUP(I43,GRAFO!L5:L44,1,0)<>"",1,0) -> #N/A | M43: =IFERROR(L43,0) -> 0 | O43: =D43 & "-" & E43 & "-" & F43 -> md-c2rm:applied_to-dmed | T43: =IF(INDEX(GRAFO!$M$2:'GRAFO'!$M$41,MATCH(O43,GRAFO!$M$2:'GRAFO'!$M$41,0),1)<>0,1,0) -> #N/A | U43: =IFERROR(T43,0) -> 0
A44: estabelece | B44: c2rm:applied_to | C44: =IF(INDEX($A$3:$B$24,MATCH(D7,$A$3:$A$24,0),2)<>0,"OK","NOK") -> OK | D44: =IF(INDEX($A$3:$B$25,MATCH(D7,$A$3:$A$25,0),2)<>0,INDEX($A$3:$B$25,MATCH(D7,$A$3:$A$25,0),2),D7) -> comandos_operacionais | E44: =IF(INDEX($A$40:$B$58,MATCH(E7,$A$40:$A$58,0),2)<>0,INDEX($A$40:$B$58,MATCH(E7,$A$40:$A$58,0),2),E7) -> c2rm:responsible_for | F44: =IF(INDEX($A$3:$B$25,MATCH(F7,$A$3:$A$25,0),2)<>0,INDEX($A$3:$B$25,MATCH(F7,$A$3:$A$25,0),2),F7) -> operacao_conjunta | G44: =IF(INDEX($A$3:$B$36,MATCH(F7,$A$3:$A$36,0),2)<>0,"OK","NOK") -> OK | I44: =D44 &"-"&F44 -> comandos_operacionais-operacao_conjunta | L44: =IF(VLOOKUP(I44,GRAFO!L6:L45,1,0)<>"",1,0) -> #N/A | M44: =IFERROR(L44,0) -> 0 | O44: =D44 & "-" & E44 & "-" & F44 -> comandos_operacionais-c2rm:responsible_for-operacao_conjunta | T44: =IF(INDEX(GRAFO!$M$2:'GRAFO'!$M$41,MATCH(O44,GRAFO!$M$2:'GRAFO'!$M$41,0),1)<>0,1,0) -> #N/A | U44: =IFERROR(T44,0) -> 0
A45: comanda | B45: c2rm:responsible_for | C45: =IF(INDEX($A$3:$B$24,MATCH(D8,$A$3:$A$24,0),2)<>0,"OK","NOK") -> NOK | D45: =IF(INDEX($A$3:$B$25,MATCH(D8,$A$3:$A$25,0),2)<>0,INDEX($A$3:$B$25,MATCH(D8,$A$3:$A$25,0),2),D8) -> md | E45: =IF(INDEX($A$40:$B$58,MATCH(E8,$A$40:$A$58,0),2)<>0,INDEX($A$40:$B$58,MATCH(E8,$A$40:$A$58,0),2),E8) -> c2rm:responsible_for | F45: =IF(INDEX($A$3:$B$25,MATCH(F8,$A$3:$A$25,0),2)<>0,INDEX($A$3:$B$25,MATCH(F8,$A$3:$A$25,0),2),F8) -> forcas_armadas | G45: =IF(INDEX($A$3:$B$36,MATCH(F8,$A$3:$A$36,0),2)<>0,"OK","NOK") -> OK | I45: =D45 &"-"&F45 -> md-forcas_armadas | L45: =IF(VLOOKUP(I45,GRAFO!L7:L46,1,0)<>"",1,0) -> #N/A | M45: =IFERROR(L45,0) -> 0 | O45: =D45 & "-" & E45 & "-" & F45 -> md-c2rm:responsible_for-forcas_armadas | T45: =IF(INDEX(GRAFO!$M$2:'GRAFO'!$M$41,MATCH(O45,GRAFO!$M$2:'GRAFO'!$M$41,0),1)<>0,1,0) -> #N/A | U45: =IFERROR(T45,0) -> 0
A46: pertence | B46: rdfs:seeAlso | C46: =IF(INDEX($A$3:$B$24,MATCH(D9,$A$3:$A$24,0),2)<>0,"OK","NOK") -> OK | D46: =IF(INDEX($A$3:$B$25,MATCH(D9,$A$3:$A$25,0),2)<>0,INDEX($A$3:$B$25,MATCH(D9,$A$3:$A$25,0),2),D9) -> aeronautica | E46: =IF(INDEX($A$40:$B$58,MATCH(E9,$A$40:$A$58,0),2)<>0,INDEX($A$40:$B$58,MATCH(E9,$A$40:$A$58,0),2),E9) -> rdfs:subClassOf | F46: =IF(INDEX($A$3:$B$25,MATCH(F9,$A$3:$A$25,0),2)<>0,INDEX($A$3:$B$25,MATCH(F9,$A$3:$A$25,0),2),F9) -> forcas_armadas | G46: =IF(INDEX($A$3:$B$36,MATCH(F9,$A$3:$A$36,0),2)<>0,"OK","NOK") -> OK | I46: =D46 &"-"&F46 -> aeronautica-forcas_armadas | L46: =IF(VLOOKUP(I46,GRAFO!L8:L47,1,0)<>"",1,0) -> 1 | M46: =IFERROR(L46,0) -> 1 | O46: =D46 & "-" & E46 & "-" & F46 -> aeronautica-rdfs:subClassOf-forcas_armadas | T46: =IF(INDEX(GRAFO!$M$2:'GRAFO'!$M$41,MATCH(O46,GRAFO!$M$2:'GRAFO'!$M$41,0),1)<>0,1,0) -> 1 | U46: =IFERROR(T46,0) -> 1
...

Sheet MODELAGEM_5
A1: ATIVIDADE 1: Mapear entidades | D1: ATIVIDADE 3: Mapear triplas (ME x MR)
A2: Entidades de MC (Ei) | B2: Entidades de KG (Ek) | D2: Sujeito MC (Ei_1) | E2: Predicado KG (Rj) | F2: Objeto MC (Ei_2) | J2: RELAÇÕES | Y2: ENTIDADES_GRAFO | AC2: R1 | AD2: equivalent_to | AE2: owl:equivalentClass
A3: nivel_op | B3: nivel | D3: politico | E3: especialization | F3: nivel_op | J3: rdf:type | M3: N. ELEM {A} | N3: N. ELEM {B} | O3: TP | P3: TN | Q3: FN | R3: FP | S3: COMPATÍVEIS | T3: INCOMPATÍVEIS | U3: PRECISÃO | V3: COBERTURA | W3: ACURÁCIA | Y3: aeronautica | AC3: R2 | AD3: associated_with | AE3: rdfs:seeAlso
A4: politico | B4: politico | D4: estrategico | E4: especialization | F4: nivel_op | K4: B | L4: ENTIDADES | M4: =GRAFO!J2 -> 29 | N4: =COUNTA(A3:A23) -> 21 | O4: =COUNTIF(B3:B23,"<>"&"") -> 14 | P4: =N4-R4 -> 14 | Q4: =M4-O4 -> 15 | R4: =N4-O4 -> 7 | S4: =O4+P4 -> 28 | T4: =Q4+R4 -> 22 | U4: =O4/(O4+R4) -> 0.66666667 | V4: =O4/(O4+Q4) -> 0.48275862 | W4: =(O4+P4)/(O4+P4+Q4+R4) -> 0.56 | X4: =AVERAGE(U4:W4) -> 0.56980843 | Y4: comandante_supremo | AC4: R3 | AD4: composed_of | AE4: rdf:Bag
A5: estrategico | B5: estrategico | D5: operacional | E5: especialization | F5: nivel_op | L5: RELAÇÕES (SR) | M5: =GRAFO!J3 -> 41 | N5: =COUNTA(D37:D60) -> 24 | O5: =COUNTIF(M37:M60,"=1") -> 7 | P5: =N5-R5 -> 7 | Q5: =M5-O5 -> 34 | R5: =N5-O5 -> 17 | S5: =O5+P5 -> 14 | T5: =Q5+R5 -> 51 | U5: =O5/(O5+R5) -> 0.29166667 | V5: =O5/(O5+Q5) -> 0.17073171 | W5: =(O5+P5)/(O5+P5+Q5+R5) -> 0.21538462 | X5: =AVERAGE(U5:W5) -> 0.22592766 | Y5: comando_e_controle | AC5: R4 | AD5: type_of | AE5: rdfs:subClassOf
A6: operacional | B6: operacional | D6: tatico | E6: especialization | F6: nivel_op | L6: RELAÇÕES (CR) | M6: 41 | N6: =COUNTA(D37:D60) -> 24 | O6: =COUNTIF(U37:U60,"=1") -> 11 | P6: =N6-R6 -> 11 | Q6: =M6-O6 -> 30 | R6: =N6-O6 -> 13 | S6: =O6+P6 -> 22 | T6: =Q6+R6 -> 43 | U6: =O6/(O6+R6) -> 0.45833333 | V6: =O6/(O6+Q6) -> 0.26829268 | W6: =(O6+P6)/(O6+P6+Q6+R6) -> 0.33846154 | X6: =AVERAGE(U6:W6) -> 0.35502918 | Y6: comando_supremo | AC6: R5 | AD6: defined_by | AE6: rdfs:comment
A7: tatico | B7: tatico | D7: cs | E7: define | F7: obj_politicos | X7: =AVERAGE(X4:X6) -> 0.38358843 | Y7: comandos_operacionais | AC7: R6 | AD7: co-referenced | AE7: c2rm:coreferenced
A8: cs | B8: comando_supremo | D8: cs | E8: comanda | F8: politico | Y8: defesa_da_patria | AC8: R7 | AD8: instance_of | AE8: rdf:type
A9: md | D9: md | E9: integra | F9: estrategico | K9: A | L9: A_E (GRAFO) | N9: =GRAFO!J2 -> 29 | Y9: emprego | AC9: R8 | AD9: responsible_for | AE9: c2rm:responsible_for
A10: obj_politicos | B10: objetivos_politicos | D10: md | E10: estabelece | F10: planos_logistico | K10: B | L10: B_E (M1) | N10: =N4 -> 21 | Y10: entity | AC10: R9 | AD10: capacity_of | AE10: c2rm:capacity_of
A11: planos_logistico | D11: md | E11: estabelece | F11: diretrizes | K11: TP | L11: (A INT B) | N11: 16 | Y11: estrategico | AC11: R10 | AD11: occurs_in | AE11: c2rm:occurs_in
A12: diretrizes | D12: fa | E12: subordinada | F12: md | K12: FN | L12: A-(A INT B) | M12: A-TP | N12: =N9-N11 -> 13 | Y12: estruturas | AC12: R11 | AD12: applied_to | AE12: c2rm:applied_to
A13: op_cj | B13: operacao_conjunta | D13: fcte | E13: resposavel | F13: pln_exec_ordens | K13: FP | L13: B-(A INT B) | M13: B-TP | Y13: exercito
A14: pln_exec_ordens | D14: fcte | E14: resposavel | F14: tatico | K14: TN | M14: B-FP | Y14: forca_aerea
A15: c_log | D15: ar | E15: empregado | F15: meios_defesa | K15: P | M15: VP/(VP+FP) | Y15: forca_componente
A16: fa | B16: forcas_armadas | D16: eb | E16: especialization | F16: fa | K16: R | M16: VP/(VP+FN) | Y16: forca_naval
A17: c_op | B17: comandos_operacionais | D17: mb | E17: especialization | F17: fa | K17: F1 | M17: (2 X P X C) / (P+C) | Y17: forca_terrestre
A18: meios_defesa | D18: fab | E18: especialization | F18: fa | K18: ACERTOS | M18: VP+VN | Y18: forcas_armadas
A19: eb | B19: exercito | D19: fa | E19: composta | F19: fcte | K19: ERROS | M19: FP+FN | Y19: heterogeneidade_dos_processos_de_emeprego
A20: mb | B20: marinha | D20: fa | E20: envolve | F20: op_cj | K20: ACURACIA | M20: (VP+VN)/(VP+FN+VN+FP) | Y20: inteligencia
A21: fab | B21: aeronautica | D21: c_log | E21: conduz | F21: op_cj | Y21: logistica
A22: ar | D22: c_log | E22: apoia | F22: c_op | Y22: marinha
A23: fcte | B23: forca_componente | D23: c_op | E23: coordena | F23: meios_defesa | Y23: nivel
D24: op_cj | E24: organizada | F24: nivel_op | Y24: objetivos_politicos
D25: fcte | E25: coordena | F25: op_cj | Y25: operacao
